{"api": "Iterator.next", "prompt": "A chat between a curious user and an artificial intelligence assistant. The assistant gives helpful, detailed, and polite answers to the user's questions. USER: Please answer my code questions using the given API following this format: <<<api>>>: $API\n<<<code>>>: $CODE\n<<<explanation>>>: $EXPLANATION.\nQuestion: removing object from arraylist using foreach exception occurs only when the list size above 2: :I have the below class for checking removing of object from arraylist by using foreach loopimport java.util.ArrayList;    public class CheckArrayList {        /**         * @return the a         */        public int getA() {            return a;        }        /**         * @param a         *            the a to set         */        public void setA(int a) {            this.a = a;        }        /**         * @return the b         */        public int getB() {            return b;        }        /**         * @param b         *            the b to set         */        public void setB(int b) {            this.b = b;        }        int a;        int b;        public static void main(String[] args) {            try {                CheckArrayList checkArrayList1 = new CheckArrayList();                checkArrayList1.setA(10);                checkArrayList1.setB(20);                CheckArrayList checkArrayList2 = new CheckArrayList();                checkArrayList2.setA(30);                checkArrayList2.setB(40);                ArrayList<CheckArrayList> aList = new ArrayList<CheckArrayList>();                aList.add(checkArrayList1);                aList.add(checkArrayList2);                System.out.println(\"size of list before iterate = \" + aList.size());                for (CheckArrayList checkArrayList : aList) {                    aList.remove(checkArrayList);                    System.out.println(\"inside loop\");                }                System.out.println(\"size of list after iterate = \" + aList.size());            } catch (Exception e) {                e.printStackTrace();            }        }    }while doing above operation it is not showing any exception but it comes inside the loop only once.if I add one more object to ist and doing same operation it showing java.util.ConcurrentModificationExceptionimport java.util.ArrayList;public class CheckArrayList {    /**     * @return the a     */    public int getA() {        return a;    }    /**     * @param a     *            the a to set     */    public void setA(int a) {        this.a = a;    }    /**     * @return the b     */    public int getB() {        return b;    }    /**     * @param b     *            the b to set     */    public void setB(int b) {        this.b = b;    }    int a;    int b;    public static void main(String[] args) {        try {            CheckArrayList checkArrayList1 = new CheckArrayList();            checkArrayList1.setA(10);            checkArrayList1.setB(20);            CheckArrayList checkArrayList2 = new CheckArrayList();            checkArrayList2.setA(30);            checkArrayList2.setB(40);            CheckArrayList checkArrayList3 = new CheckArrayList();            checkArrayList3.setA(30);            checkArrayList3.setB(40);            ArrayList<CheckArrayList> aList = new ArrayList<CheckArrayList>();            aList.add(checkArrayList1);            aList.add(checkArrayList2);            aList.add(checkArrayList3);            System.out.println(\"size of list before iterate = \" + aList.size());            for (CheckArrayList checkArrayList : aList) {                aList.remove(checkArrayList);                System.out.println(\"inside loop\");            }            System.out.println(\"size of list after iterate = \" + aList.size());        } catch (Exception e) {            e.printStackTrace();        }    }}why it not showing exception if arralist size equal to 2?\nPlease using this api: Iterator.next.\nAnswer: ASSISTANT:", "response": "The reason why the exception is not thrown when the size of the ArrayList is equal to 2 is because the Iterator.next() method is used to retrieve the next element in the iterator, which moves the internal cursor of the iterator to the next element. In the case of an ArrayList with only two elements, the internal cursor is already pointing to the second element, so calling Iterator.next() does not throw an exception.\n\nHowever, when a new element is added to the ArrayList while iterating over it, the internal cursor is moved to the new element, and calling Iterator.next() again will throw a ConcurrentModificationException. This is because the iteration is occurring concurrently with the modification of the ArrayList, and the iterator is no longer pointing to the correct element.\n\nTo avoid this exception, you can use the Iterator.remove() method instead of the for-each loop, which does not modify the iterator and will not throw a ConcurrentModificationException."}