{"api": "Iterator.next", "prompt": "A chat between a curious user and an artificial intelligence assistant. The assistant gives helpful, detailed, and polite answers to the user's questions. USER: Please answer my code questions using the given API following this format: <<<api>>>: $API\n<<<code>>>: $CODE\n<<<explanation>>>: $EXPLANATION.\nQuestion: How can I calculate the sum of an array in Java?\nPlease using this api: Arrays.stream.\nAnswer:<<<api>>>: Arrays.stream\n<<<code>>>: int[] array = {1, 2, 3, 4, 5};\nint sum = Arrays.stream(array).sum();\n<<<explanation>>>: The sum() method of the IntStream class returns the sum of elements in this stream. This is a special case of a reduction. This is a terminal operation.\nQuestion: removing object from arraylist using foreach exception occurs only when the list size above 2: :I have the below class for checking removing of object from arraylist by using foreach loopimport java.util.ArrayList;    public class CheckArrayList {        /**         * @return the a         */        public int getA() {            return a;        }        /**         * @param a         *            the a to set         */        public void setA(int a) {            this.a = a;        }        /**         * @return the b         */        public int getB() {            return b;        }        /**         * @param b         *            the b to set         */        public void setB(int b) {            this.b = b;        }        int a;        int b;        public static void main(String[] args) {            try {                CheckArrayList checkArrayList1 = new CheckArrayList();                checkArrayList1.setA(10);                checkArrayList1.setB(20);                CheckArrayList checkArrayList2 = new CheckArrayList();                checkArrayList2.setA(30);                checkArrayList2.setB(40);                ArrayList<CheckArrayList> aList = new ArrayList<CheckArrayList>();                aList.add(checkArrayList1);                aList.add(checkArrayList2);                System.out.println(\"size of list before iterate = \" + aList.size());                for (CheckArrayList checkArrayList : aList) {                    aList.remove(checkArrayList);                    System.out.println(\"inside loop\");                }                System.out.println(\"size of list after iterate = \" + aList.size());            } catch (Exception e) {                e.printStackTrace();            }        }    }while doing above operation it is not showing any exception but it comes inside the loop only once.if I add one more object to ist and doing same operation it showing java.util.ConcurrentModificationExceptionimport java.util.ArrayList;public class CheckArrayList {    /**     * @return the a     */    public int getA() {        return a;    }    /**     * @param a     *            the a to set     */    public void setA(int a) {        this.a = a;    }    /**     * @return the b     */    public int getB() {        return b;    }    /**     * @param b     *            the b to set     */    public void setB(int b) {        this.b = b;    }    int a;    int b;    public static void main(String[] args) {        try {            CheckArrayList checkArrayList1 = new CheckArrayList();            checkArrayList1.setA(10);            checkArrayList1.setB(20);            CheckArrayList checkArrayList2 = new CheckArrayList();            checkArrayList2.setA(30);            checkArrayList2.setB(40);            CheckArrayList checkArrayList3 = new CheckArrayList();            checkArrayList3.setA(30);            checkArrayList3.setB(40);            ArrayList<CheckArrayList> aList = new ArrayList<CheckArrayList>();            aList.add(checkArrayList1);            aList.add(checkArrayList2);            aList.add(checkArrayList3);            System.out.println(\"size of list before iterate = \" + aList.size());            for (CheckArrayList checkArrayList : aList) {                aList.remove(checkArrayList);                System.out.println(\"inside loop\");            }            System.out.println(\"size of list after iterate = \" + aList.size());        } catch (Exception e) {            e.printStackTrace();        }    }}why it not showing exception if arralist size equal to 2?\nPlease using this api: Iterator.next.\nAnswer: ASSISTANT:", "response": "<<<api>>>: Iterator.next\n<<<code>>>: ArrayList<CheckArrayList> aList = new ArrayList<CheckArrayList>();\naList.add(checkArrayList1);\naList.add(checkArrayList2);\nIterator<CheckArrayList> iterator = aList.iterator();\nwhile (iterator.hasNext()) {\nCheckArrayList checkArrayList = iterator.next();\naList.remove(checkArrayList);\n}\nSystem.out.println(\"size of list after iterate = \" + aList.size());\n<<<explanation>>>: The hasNext() method of the Iterator interface returns true if there is at least one more element in the iteration. The next() method of the Iterator interface returns the next element in the iteration. In this case, we are using a for-each loop to iterate through the ArrayList and remove each element using the next() method of the Iterator. The hasNext() method is used to check if there is at least one more element to remove."}